nohup: ignoring input
INFO:     Started server process [23163]
INFO:     Waiting for application startup.
INFO:     Application startup complete.
INFO:     Uvicorn running on http://0.0.0.0:8090 (Press CTRL+C to quit)
INFO:     2003:f3:2f17:c400:cbb4:c8f:f52d:b0a9:0 - "POST /stop-boost HTTP/1.0" 200 OK
INFO:     2003:f3:2f17:c400:cbb4:c8f:f52d:b0a9:0 - "POST /stop-boost HTTP/1.0" 200 OK
INFO:     2003:f3:2f17:c400:cbb4:c8f:f52d:b0a9:0 - "POST /stop-temporary-charge HTTP/1.0" 200 OK
INFO:     2a00:fbc:ef30:f71a::2:0 - "POST /temporary-charge HTTP/1.0" 200 OK
INFO:     2003:f3:2f28:41fc:65ce:3432:3719:f7dd:0 - "POST /stop-temporary-charge HTTP/1.0" 200 OK
INFO:     2003:f3:2f28:41fc:65ce:3432:3719:f7dd:0 - "POST /temporary-charge HTTP/1.0" 200 OK
INFO:     2003:f3:2f28:41fc:65ce:3432:3719:f7dd:0 - "POST /stop-temporary-charge HTTP/1.0" 200 OK
INFO:     84.135.104.245:0 - "POST /boost HTTP/1.0" 200 OK
INFO:     2a00:fbc:ecfd:83ab::2:0 - "POST /temporary-charge HTTP/1.0" 500 Internal Server Error
ERROR:    Exception in ASGI application
Traceback (most recent call last):
  File "/root/pycontrl/ctrlvenv/lib/python3.10/site-packages/uvicorn/protocols/http/h11_impl.py", line 403, in run_asgi
    result = await app(  # type: ignore[func-returns-value]
  File "/root/pycontrl/ctrlvenv/lib/python3.10/site-packages/uvicorn/middleware/proxy_headers.py", line 60, in __call__
    return await self.app(scope, receive, send)
  File "/root/pycontrl/ctrlvenv/lib/python3.10/site-packages/fastapi/applications.py", line 1054, in __call__
    await super().__call__(scope, receive, send)
  File "/root/pycontrl/ctrlvenv/lib/python3.10/site-packages/starlette/applications.py", line 113, in __call__
    await self.middleware_stack(scope, receive, send)
  File "/root/pycontrl/ctrlvenv/lib/python3.10/site-packages/starlette/middleware/errors.py", line 186, in __call__
    raise exc
  File "/root/pycontrl/ctrlvenv/lib/python3.10/site-packages/starlette/middleware/errors.py", line 164, in __call__
    await self.app(scope, receive, _send)
  File "/root/pycontrl/ctrlvenv/lib/python3.10/site-packages/starlette/middleware/cors.py", line 93, in __call__
    await self.simple_response(scope, receive, send, request_headers=headers)
  File "/root/pycontrl/ctrlvenv/lib/python3.10/site-packages/starlette/middleware/cors.py", line 144, in simple_response
    await self.app(scope, receive, send)
  File "/root/pycontrl/ctrlvenv/lib/python3.10/site-packages/starlette/middleware/exceptions.py", line 63, in __call__
    await wrap_app_handling_exceptions(self.app, conn)(scope, receive, send)
  File "/root/pycontrl/ctrlvenv/lib/python3.10/site-packages/starlette/_exception_handler.py", line 53, in wrapped_app
    raise exc
  File "/root/pycontrl/ctrlvenv/lib/python3.10/site-packages/starlette/_exception_handler.py", line 42, in wrapped_app
    await app(scope, receive, sender)
  File "/root/pycontrl/ctrlvenv/lib/python3.10/site-packages/starlette/routing.py", line 716, in __call__
    await self.middleware_stack(scope, receive, send)
  File "/root/pycontrl/ctrlvenv/lib/python3.10/site-packages/starlette/routing.py", line 736, in app
    await route.handle(scope, receive, send)
  File "/root/pycontrl/ctrlvenv/lib/python3.10/site-packages/starlette/routing.py", line 290, in handle
    await self.app(scope, receive, send)
  File "/root/pycontrl/ctrlvenv/lib/python3.10/site-packages/starlette/routing.py", line 78, in app
    await wrap_app_handling_exceptions(app, request)(scope, receive, send)
  File "/root/pycontrl/ctrlvenv/lib/python3.10/site-packages/starlette/_exception_handler.py", line 53, in wrapped_app
    raise exc
  File "/root/pycontrl/ctrlvenv/lib/python3.10/site-packages/starlette/_exception_handler.py", line 42, in wrapped_app
    await app(scope, receive, sender)
  File "/root/pycontrl/ctrlvenv/lib/python3.10/site-packages/starlette/routing.py", line 75, in app
    response = await f(request)
  File "/root/pycontrl/ctrlvenv/lib/python3.10/site-packages/fastapi/routing.py", line 302, in app
    raw_response = await run_endpoint_function(
  File "/root/pycontrl/ctrlvenv/lib/python3.10/site-packages/fastapi/routing.py", line 215, in run_endpoint_function
    return await run_in_threadpool(dependant.call, **values)
  File "/root/pycontrl/ctrlvenv/lib/python3.10/site-packages/starlette/concurrency.py", line 38, in run_in_threadpool
    return await anyio.to_thread.run_sync(func)
  File "/root/pycontrl/ctrlvenv/lib/python3.10/site-packages/anyio/to_thread.py", line 56, in run_sync
    return await get_async_backend().run_sync_in_worker_thread(
  File "/root/pycontrl/ctrlvenv/lib/python3.10/site-packages/anyio/_backends/_asyncio.py", line 2470, in run_sync_in_worker_thread
    return await future
  File "/root/pycontrl/ctrlvenv/lib/python3.10/site-packages/anyio/_backends/_asyncio.py", line 967, in run
    result = context.run(func, *args)
  File "/root/pycontrl/v1.2/boost_api.py", line 43, in temporary_charge
    send_udp_message_and_receive_response("curr 6000")
  File "/root/pycontrl/v1.2/utils.py", line 82, in send_udp_message_and_receive_response
    sock.bind(('', port))  # Bind to same port to receive response (optional)
OSError: [Errno 98] Address already in use
INFO:     2a00:fbc:ecfd:83ab::2:0 - "POST /temporary-charge HTTP/1.0" 200 OK
INFO:     2a00:fbc:ecfd:83ab::2:0 - "POST /temporary-charge HTTP/1.0" 200 OK
INFO:     2a00:fbc:ecfd:83ab::2:0 - "POST /temporary-charge HTTP/1.0" 200 OK
INFO:     2a00:fbc:ecfd:83ab::2:0 - "POST /boost HTTP/1.0" 200 OK
INFO:     2a00:fbc:ecfd:83ab::2:0 - "POST /temporary-charge HTTP/1.0" 200 OK
INFO:     2a00:fbc:ecfd:83ab::2:0 - "POST /boost HTTP/1.0" 200 OK
INFO:     2a00:fbc:ecfd:83ab::2:0 - "POST /boost HTTP/1.0" 500 Internal Server Error
ERROR:    Exception in ASGI application
Traceback (most recent call last):
  File "/root/pycontrl/ctrlvenv/lib/python3.10/site-packages/uvicorn/protocols/http/h11_impl.py", line 403, in run_asgi
    result = await app(  # type: ignore[func-returns-value]
  File "/root/pycontrl/ctrlvenv/lib/python3.10/site-packages/uvicorn/middleware/proxy_headers.py", line 60, in __call__
    return await self.app(scope, receive, send)
  File "/root/pycontrl/ctrlvenv/lib/python3.10/site-packages/fastapi/applications.py", line 1054, in __call__
    await super().__call__(scope, receive, send)
  File "/root/pycontrl/ctrlvenv/lib/python3.10/site-packages/starlette/applications.py", line 113, in __call__
    await self.middleware_stack(scope, receive, send)
  File "/root/pycontrl/ctrlvenv/lib/python3.10/site-packages/starlette/middleware/errors.py", line 186, in __call__
    raise exc
  File "/root/pycontrl/ctrlvenv/lib/python3.10/site-packages/starlette/middleware/errors.py", line 164, in __call__
    await self.app(scope, receive, _send)
  File "/root/pycontrl/ctrlvenv/lib/python3.10/site-packages/starlette/middleware/cors.py", line 93, in __call__
    await self.simple_response(scope, receive, send, request_headers=headers)
  File "/root/pycontrl/ctrlvenv/lib/python3.10/site-packages/starlette/middleware/cors.py", line 144, in simple_response
    await self.app(scope, receive, send)
  File "/root/pycontrl/ctrlvenv/lib/python3.10/site-packages/starlette/middleware/exceptions.py", line 63, in __call__
    await wrap_app_handling_exceptions(self.app, conn)(scope, receive, send)
  File "/root/pycontrl/ctrlvenv/lib/python3.10/site-packages/starlette/_exception_handler.py", line 53, in wrapped_app
    raise exc
  File "/root/pycontrl/ctrlvenv/lib/python3.10/site-packages/starlette/_exception_handler.py", line 42, in wrapped_app
    await app(scope, receive, sender)
  File "/root/pycontrl/ctrlvenv/lib/python3.10/site-packages/starlette/routing.py", line 716, in __call__
    await self.middleware_stack(scope, receive, send)
  File "/root/pycontrl/ctrlvenv/lib/python3.10/site-packages/starlette/routing.py", line 736, in app
    await route.handle(scope, receive, send)
  File "/root/pycontrl/ctrlvenv/lib/python3.10/site-packages/starlette/routing.py", line 290, in handle
    await self.app(scope, receive, send)
  File "/root/pycontrl/ctrlvenv/lib/python3.10/site-packages/starlette/routing.py", line 78, in app
    await wrap_app_handling_exceptions(app, request)(scope, receive, send)
  File "/root/pycontrl/ctrlvenv/lib/python3.10/site-packages/starlette/_exception_handler.py", line 53, in wrapped_app
    raise exc
  File "/root/pycontrl/ctrlvenv/lib/python3.10/site-packages/starlette/_exception_handler.py", line 42, in wrapped_app
    await app(scope, receive, sender)
  File "/root/pycontrl/ctrlvenv/lib/python3.10/site-packages/starlette/routing.py", line 75, in app
    response = await f(request)
  File "/root/pycontrl/ctrlvenv/lib/python3.10/site-packages/fastapi/routing.py", line 302, in app
    raw_response = await run_endpoint_function(
  File "/root/pycontrl/ctrlvenv/lib/python3.10/site-packages/fastapi/routing.py", line 215, in run_endpoint_function
    return await run_in_threadpool(dependant.call, **values)
  File "/root/pycontrl/ctrlvenv/lib/python3.10/site-packages/starlette/concurrency.py", line 38, in run_in_threadpool
    return await anyio.to_thread.run_sync(func)
  File "/root/pycontrl/ctrlvenv/lib/python3.10/site-packages/anyio/to_thread.py", line 56, in run_sync
    return await get_async_backend().run_sync_in_worker_thread(
  File "/root/pycontrl/ctrlvenv/lib/python3.10/site-packages/anyio/_backends/_asyncio.py", line 2470, in run_sync_in_worker_thread
    return await future
  File "/root/pycontrl/ctrlvenv/lib/python3.10/site-packages/anyio/_backends/_asyncio.py", line 967, in run
    result = context.run(func, *args)
  File "/root/pycontrl/v1.2/boost_api.py", line 26, in activate_boost
    send_udp_message_and_receive_response("curr 16000")
  File "/root/pycontrl/v1.2/utils.py", line 82, in send_udp_message_and_receive_response
    sock.bind(('', port))  # Bind to same port to receive response (optional)
OSError: [Errno 98] Address already in use
INFO:     2a00:fbc:ecfd:83ab::2:0 - "POST /boost HTTP/1.0" 200 OK
INFO:     2a00:fbc:ecfd:83ab::2:0 - "POST /temporary-charge HTTP/1.0" 200 OK
INFO:     2a00:fbc:ecfd:83ab::2:0 - "POST /stop-temporary-charge HTTP/1.0" 200 OK
INFO:     84.135.104.245:0 - "POST /temporary-charge HTTP/1.0" 200 OK
INFO:     2003:f3:2f28:4100:75c4:36f5:23a0:a07f:0 - "POST /stop-temporary-charge HTTP/1.0" 200 OK
INFO:     2a02:3038:607:b33b:fccf:d477:8d5a:c216:0 - "POST /temporary-charge HTTP/1.0" 200 OK
INFO:     2a02:3038:607:b33b:fccf:d477:8d5a:c216:0 - "POST /temporary-charge HTTP/1.0" 200 OK
INFO:     2003:f3:2f17:c400:75c4:36f5:23a0:a07f:0 - "POST /temporary-charge HTTP/1.0" 200 OK
INFO:     2003:f3:2f17:c400:75c4:36f5:23a0:a07f:0 - "POST /temporary-charge HTTP/1.0" 200 OK
INFO:     2003:f3:2f17:c400:75c4:36f5:23a0:a07f:0 - "POST /temporary-charge HTTP/1.0" 200 OK
INFO:     2003:f3:2f17:c400:75c4:36f5:23a0:a07f:0 - "POST /temporary-charge HTTP/1.0" 200 OK
INFO:     2003:f3:2f17:c400:75c4:36f5:23a0:a07f:0 - "POST /temporary-charge HTTP/1.0" 200 OK
INFO:     2003:f3:2f17:c400:75c4:36f5:23a0:a07f:0 - "POST /temporary-charge HTTP/1.0" 200 OK
INFO:     2a02:3038:607:b33b:fccf:d477:8d5a:c216:0 - "POST /temporary-charge HTTP/1.0" 200 OK
INFO:     2003:f3:2f17:c400:75c4:36f5:23a0:a07f:0 - "POST /temporary-charge HTTP/1.0" 200 OK
INFO:     176.3.136.199:0 - "POST /temporary-charge HTTP/1.0" 200 OK
INFO:     88.217.234.182:0 - "POST /boost HTTP/1.0" 200 OK
INFO:     88.217.234.182:0 - "POST /stop-boost HTTP/1.0" 200 OK
INFO:     2003:f3:2f17:c400:75c4:36f5:23a0:a07f:0 - "POST /stop-boost HTTP/1.0" 200 OK
INFO:     2003:f3:2f17:c400:75c4:36f5:23a0:a07f:0 - "POST /temporary-charge HTTP/1.0" 200 OK
INFO:     88.217.234.182:0 - "POST /stop-temporary-charge HTTP/1.0" 200 OK
INFO:     88.217.234.182:0 - "POST /temporary-charge HTTP/1.0" 500 Internal Server Error
ERROR:    Exception in ASGI application
Traceback (most recent call last):
  File "/root/pycontrl/ctrlvenv/lib/python3.10/site-packages/uvicorn/protocols/http/h11_impl.py", line 403, in run_asgi
    result = await app(  # type: ignore[func-returns-value]
  File "/root/pycontrl/ctrlvenv/lib/python3.10/site-packages/uvicorn/middleware/proxy_headers.py", line 60, in __call__
    return await self.app(scope, receive, send)
  File "/root/pycontrl/ctrlvenv/lib/python3.10/site-packages/fastapi/applications.py", line 1054, in __call__
    await super().__call__(scope, receive, send)
  File "/root/pycontrl/ctrlvenv/lib/python3.10/site-packages/starlette/applications.py", line 113, in __call__
    await self.middleware_stack(scope, receive, send)
  File "/root/pycontrl/ctrlvenv/lib/python3.10/site-packages/starlette/middleware/errors.py", line 186, in __call__
    raise exc
  File "/root/pycontrl/ctrlvenv/lib/python3.10/site-packages/starlette/middleware/errors.py", line 164, in __call__
    await self.app(scope, receive, _send)
  File "/root/pycontrl/ctrlvenv/lib/python3.10/site-packages/starlette/middleware/cors.py", line 93, in __call__
    await self.simple_response(scope, receive, send, request_headers=headers)
  File "/root/pycontrl/ctrlvenv/lib/python3.10/site-packages/starlette/middleware/cors.py", line 144, in simple_response
    await self.app(scope, receive, send)
  File "/root/pycontrl/ctrlvenv/lib/python3.10/site-packages/starlette/middleware/exceptions.py", line 63, in __call__
    await wrap_app_handling_exceptions(self.app, conn)(scope, receive, send)
  File "/root/pycontrl/ctrlvenv/lib/python3.10/site-packages/starlette/_exception_handler.py", line 53, in wrapped_app
    raise exc
  File "/root/pycontrl/ctrlvenv/lib/python3.10/site-packages/starlette/_exception_handler.py", line 42, in wrapped_app
    await app(scope, receive, sender)
  File "/root/pycontrl/ctrlvenv/lib/python3.10/site-packages/starlette/routing.py", line 716, in __call__
    await self.middleware_stack(scope, receive, send)
  File "/root/pycontrl/ctrlvenv/lib/python3.10/site-packages/starlette/routing.py", line 736, in app
    await route.handle(scope, receive, send)
  File "/root/pycontrl/ctrlvenv/lib/python3.10/site-packages/starlette/routing.py", line 290, in handle
    await self.app(scope, receive, send)
  File "/root/pycontrl/ctrlvenv/lib/python3.10/site-packages/starlette/routing.py", line 78, in app
    await wrap_app_handling_exceptions(app, request)(scope, receive, send)
  File "/root/pycontrl/ctrlvenv/lib/python3.10/site-packages/starlette/_exception_handler.py", line 53, in wrapped_app
    raise exc
  File "/root/pycontrl/ctrlvenv/lib/python3.10/site-packages/starlette/_exception_handler.py", line 42, in wrapped_app
    await app(scope, receive, sender)
  File "/root/pycontrl/ctrlvenv/lib/python3.10/site-packages/starlette/routing.py", line 75, in app
    response = await f(request)
  File "/root/pycontrl/ctrlvenv/lib/python3.10/site-packages/fastapi/routing.py", line 302, in app
    raw_response = await run_endpoint_function(
  File "/root/pycontrl/ctrlvenv/lib/python3.10/site-packages/fastapi/routing.py", line 215, in run_endpoint_function
    return await run_in_threadpool(dependant.call, **values)
  File "/root/pycontrl/ctrlvenv/lib/python3.10/site-packages/starlette/concurrency.py", line 38, in run_in_threadpool
    return await anyio.to_thread.run_sync(func)
  File "/root/pycontrl/ctrlvenv/lib/python3.10/site-packages/anyio/to_thread.py", line 56, in run_sync
    return await get_async_backend().run_sync_in_worker_thread(
  File "/root/pycontrl/ctrlvenv/lib/python3.10/site-packages/anyio/_backends/_asyncio.py", line 2470, in run_sync_in_worker_thread
    return await future
  File "/root/pycontrl/ctrlvenv/lib/python3.10/site-packages/anyio/_backends/_asyncio.py", line 967, in run
    result = context.run(func, *args)
  File "/root/pycontrl/v1.2/boost_api.py", line 43, in temporary_charge
    send_udp_message_and_receive_response("curr 6000")
  File "/root/pycontrl/v1.2/utils.py", line 82, in send_udp_message_and_receive_response
    sock.bind(('', port))  # Bind to same port to receive response (optional)
OSError: [Errno 98] Address already in use
INFO:     88.217.234.182:0 - "POST /temporary-charge HTTP/1.0" 200 OK
INFO:     88.217.234.182:0 - "POST /boost HTTP/1.0" 200 OK
INFO:     2003:f3:2f17:c400:75c4:36f5:23a0:a07f:0 - "POST /temporary-charge HTTP/1.0" 200 OK
INFO:     88.217.234.182:0 - "POST /stop-boost HTTP/1.0" 200 OK
INFO:     2003:f3:2f17:c400:75c4:36f5:23a0:a07f:0 - "POST /temporary-charge HTTP/1.0" 200 OK
INFO:     88.217.234.182:0 - "POST /stop-temporary-charge HTTP/1.0" 200 OK
INFO:     88.217.234.182:0 - "POST /temporary-charge HTTP/1.0" 500 Internal Server Error
ERROR:    Exception in ASGI application
Traceback (most recent call last):
  File "/root/pycontrl/ctrlvenv/lib/python3.10/site-packages/uvicorn/protocols/http/h11_impl.py", line 403, in run_asgi
    result = await app(  # type: ignore[func-returns-value]
  File "/root/pycontrl/ctrlvenv/lib/python3.10/site-packages/uvicorn/middleware/proxy_headers.py", line 60, in __call__
    return await self.app(scope, receive, send)
  File "/root/pycontrl/ctrlvenv/lib/python3.10/site-packages/fastapi/applications.py", line 1054, in __call__
    await super().__call__(scope, receive, send)
  File "/root/pycontrl/ctrlvenv/lib/python3.10/site-packages/starlette/applications.py", line 113, in __call__
    await self.middleware_stack(scope, receive, send)
  File "/root/pycontrl/ctrlvenv/lib/python3.10/site-packages/starlette/middleware/errors.py", line 186, in __call__
    raise exc
  File "/root/pycontrl/ctrlvenv/lib/python3.10/site-packages/starlette/middleware/errors.py", line 164, in __call__
    await self.app(scope, receive, _send)
  File "/root/pycontrl/ctrlvenv/lib/python3.10/site-packages/starlette/middleware/cors.py", line 93, in __call__
    await self.simple_response(scope, receive, send, request_headers=headers)
  File "/root/pycontrl/ctrlvenv/lib/python3.10/site-packages/starlette/middleware/cors.py", line 144, in simple_response
    await self.app(scope, receive, send)
  File "/root/pycontrl/ctrlvenv/lib/python3.10/site-packages/starlette/middleware/exceptions.py", line 63, in __call__
    await wrap_app_handling_exceptions(self.app, conn)(scope, receive, send)
  File "/root/pycontrl/ctrlvenv/lib/python3.10/site-packages/starlette/_exception_handler.py", line 53, in wrapped_app
    raise exc
  File "/root/pycontrl/ctrlvenv/lib/python3.10/site-packages/starlette/_exception_handler.py", line 42, in wrapped_app
    await app(scope, receive, sender)
  File "/root/pycontrl/ctrlvenv/lib/python3.10/site-packages/starlette/routing.py", line 716, in __call__
    await self.middleware_stack(scope, receive, send)
  File "/root/pycontrl/ctrlvenv/lib/python3.10/site-packages/starlette/routing.py", line 736, in app
    await route.handle(scope, receive, send)
  File "/root/pycontrl/ctrlvenv/lib/python3.10/site-packages/starlette/routing.py", line 290, in handle
    await self.app(scope, receive, send)
  File "/root/pycontrl/ctrlvenv/lib/python3.10/site-packages/starlette/routing.py", line 78, in app
    await wrap_app_handling_exceptions(app, request)(scope, receive, send)
  File "/root/pycontrl/ctrlvenv/lib/python3.10/site-packages/starlette/_exception_handler.py", line 53, in wrapped_app
    raise exc
  File "/root/pycontrl/ctrlvenv/lib/python3.10/site-packages/starlette/_exception_handler.py", line 42, in wrapped_app
    await app(scope, receive, sender)
  File "/root/pycontrl/ctrlvenv/lib/python3.10/site-packages/starlette/routing.py", line 75, in app
    response = await f(request)
  File "/root/pycontrl/ctrlvenv/lib/python3.10/site-packages/fastapi/routing.py", line 302, in app
    raw_response = await run_endpoint_function(
  File "/root/pycontrl/ctrlvenv/lib/python3.10/site-packages/fastapi/routing.py", line 215, in run_endpoint_function
    return await run_in_threadpool(dependant.call, **values)
  File "/root/pycontrl/ctrlvenv/lib/python3.10/site-packages/starlette/concurrency.py", line 38, in run_in_threadpool
    return await anyio.to_thread.run_sync(func)
  File "/root/pycontrl/ctrlvenv/lib/python3.10/site-packages/anyio/to_thread.py", line 56, in run_sync
    return await get_async_backend().run_sync_in_worker_thread(
  File "/root/pycontrl/ctrlvenv/lib/python3.10/site-packages/anyio/_backends/_asyncio.py", line 2470, in run_sync_in_worker_thread
    return await future
  File "/root/pycontrl/ctrlvenv/lib/python3.10/site-packages/anyio/_backends/_asyncio.py", line 967, in run
    result = context.run(func, *args)
  File "/root/pycontrl/v1.2/boost_api.py", line 43, in temporary_charge
    send_udp_message_and_receive_response("curr 6000")
  File "/root/pycontrl/v1.2/utils.py", line 82, in send_udp_message_and_receive_response
    sock.bind(('', port))  # Bind to same port to receive response (optional)
OSError: [Errno 98] Address already in use
INFO:     88.217.234.182:0 - "POST /temporary-charge HTTP/1.0" 200 OK
INFO:     88.217.234.182:0 - "POST /stop-temporary-charge HTTP/1.0" 200 OK
INFO:     88.217.234.182:0 - "POST /temporary-charge HTTP/1.0" 200 OK
INFO:     2a00:fbc:f3b3:c4c::2:0 - "POST /stop-boost HTTP/1.0" 500 Internal Server Error
ERROR:    Exception in ASGI application
Traceback (most recent call last):
  File "/root/pycontrl/ctrlvenv/lib/python3.10/site-packages/uvicorn/protocols/http/h11_impl.py", line 403, in run_asgi
    result = await app(  # type: ignore[func-returns-value]
  File "/root/pycontrl/ctrlvenv/lib/python3.10/site-packages/uvicorn/middleware/proxy_headers.py", line 60, in __call__
    return await self.app(scope, receive, send)
  File "/root/pycontrl/ctrlvenv/lib/python3.10/site-packages/fastapi/applications.py", line 1054, in __call__
    await super().__call__(scope, receive, send)
  File "/root/pycontrl/ctrlvenv/lib/python3.10/site-packages/starlette/applications.py", line 113, in __call__
    await self.middleware_stack(scope, receive, send)
  File "/root/pycontrl/ctrlvenv/lib/python3.10/site-packages/starlette/middleware/errors.py", line 186, in __call__
    raise exc
  File "/root/pycontrl/ctrlvenv/lib/python3.10/site-packages/starlette/middleware/errors.py", line 164, in __call__
    await self.app(scope, receive, _send)
  File "/root/pycontrl/ctrlvenv/lib/python3.10/site-packages/starlette/middleware/cors.py", line 93, in __call__
    await self.simple_response(scope, receive, send, request_headers=headers)
  File "/root/pycontrl/ctrlvenv/lib/python3.10/site-packages/starlette/middleware/cors.py", line 144, in simple_response
    await self.app(scope, receive, send)
  File "/root/pycontrl/ctrlvenv/lib/python3.10/site-packages/starlette/middleware/exceptions.py", line 63, in __call__
    await wrap_app_handling_exceptions(self.app, conn)(scope, receive, send)
  File "/root/pycontrl/ctrlvenv/lib/python3.10/site-packages/starlette/_exception_handler.py", line 53, in wrapped_app
    raise exc
  File "/root/pycontrl/ctrlvenv/lib/python3.10/site-packages/starlette/_exception_handler.py", line 42, in wrapped_app
    await app(scope, receive, sender)
  File "/root/pycontrl/ctrlvenv/lib/python3.10/site-packages/starlette/routing.py", line 716, in __call__
    await self.middleware_stack(scope, receive, send)
  File "/root/pycontrl/ctrlvenv/lib/python3.10/site-packages/starlette/routing.py", line 736, in app
    await route.handle(scope, receive, send)
  File "/root/pycontrl/ctrlvenv/lib/python3.10/site-packages/starlette/routing.py", line 290, in handle
    await self.app(scope, receive, send)
  File "/root/pycontrl/ctrlvenv/lib/python3.10/site-packages/starlette/routing.py", line 78, in app
    await wrap_app_handling_exceptions(app, request)(scope, receive, send)
  File "/root/pycontrl/ctrlvenv/lib/python3.10/site-packages/starlette/_exception_handler.py", line 53, in wrapped_app
    raise exc
  File "/root/pycontrl/ctrlvenv/lib/python3.10/site-packages/starlette/_exception_handler.py", line 42, in wrapped_app
    await app(scope, receive, sender)
  File "/root/pycontrl/ctrlvenv/lib/python3.10/site-packages/starlette/routing.py", line 75, in app
    response = await f(request)
  File "/root/pycontrl/ctrlvenv/lib/python3.10/site-packages/fastapi/routing.py", line 302, in app
    raw_response = await run_endpoint_function(
  File "/root/pycontrl/ctrlvenv/lib/python3.10/site-packages/fastapi/routing.py", line 215, in run_endpoint_function
    return await run_in_threadpool(dependant.call, **values)
  File "/root/pycontrl/ctrlvenv/lib/python3.10/site-packages/starlette/concurrency.py", line 38, in run_in_threadpool
    return await anyio.to_thread.run_sync(func)
  File "/root/pycontrl/ctrlvenv/lib/python3.10/site-packages/anyio/to_thread.py", line 56, in run_sync
    return await get_async_backend().run_sync_in_worker_thread(
  File "/root/pycontrl/ctrlvenv/lib/python3.10/site-packages/anyio/_backends/_asyncio.py", line 2470, in run_sync_in_worker_thread
    return await future
  File "/root/pycontrl/ctrlvenv/lib/python3.10/site-packages/anyio/_backends/_asyncio.py", line 967, in run
    result = context.run(func, *args)
  File "/root/pycontrl/v1.2/boost_api.py", line 34, in stop_boost
    send_udp_message_and_receive_response("curr 6000")  # reset to normal current
  File "/root/pycontrl/v1.2/utils.py", line 82, in send_udp_message_and_receive_response
    sock.bind(('', port))  # Bind to same port to receive response (optional)
OSError: [Errno 98] Address already in use
INFO:     2a00:fbc:f3b3:c4c::2:0 - "POST /stop-boost HTTP/1.0" 200 OK
INFO:     2a00:fbc:f3b3:c4c::2:0 - "POST /stop-temporary-charge HTTP/1.0" 200 OK
INFO:     2a00:fbc:f3b3:c4c::2:0 - "POST /stop-boost HTTP/1.0" 500 Internal Server Error
ERROR:    Exception in ASGI application
Traceback (most recent call last):
  File "/root/pycontrl/ctrlvenv/lib/python3.10/site-packages/uvicorn/protocols/http/h11_impl.py", line 403, in run_asgi
    result = await app(  # type: ignore[func-returns-value]
  File "/root/pycontrl/ctrlvenv/lib/python3.10/site-packages/uvicorn/middleware/proxy_headers.py", line 60, in __call__
    return await self.app(scope, receive, send)
  File "/root/pycontrl/ctrlvenv/lib/python3.10/site-packages/fastapi/applications.py", line 1054, in __call__
    await super().__call__(scope, receive, send)
  File "/root/pycontrl/ctrlvenv/lib/python3.10/site-packages/starlette/applications.py", line 113, in __call__
    await self.middleware_stack(scope, receive, send)
  File "/root/pycontrl/ctrlvenv/lib/python3.10/site-packages/starlette/middleware/errors.py", line 186, in __call__
    raise exc
  File "/root/pycontrl/ctrlvenv/lib/python3.10/site-packages/starlette/middleware/errors.py", line 164, in __call__
    await self.app(scope, receive, _send)
  File "/root/pycontrl/ctrlvenv/lib/python3.10/site-packages/starlette/middleware/cors.py", line 93, in __call__
    await self.simple_response(scope, receive, send, request_headers=headers)
  File "/root/pycontrl/ctrlvenv/lib/python3.10/site-packages/starlette/middleware/cors.py", line 144, in simple_response
    await self.app(scope, receive, send)
  File "/root/pycontrl/ctrlvenv/lib/python3.10/site-packages/starlette/middleware/exceptions.py", line 63, in __call__
    await wrap_app_handling_exceptions(self.app, conn)(scope, receive, send)
  File "/root/pycontrl/ctrlvenv/lib/python3.10/site-packages/starlette/_exception_handler.py", line 53, in wrapped_app
    raise exc
  File "/root/pycontrl/ctrlvenv/lib/python3.10/site-packages/starlette/_exception_handler.py", line 42, in wrapped_app
    await app(scope, receive, sender)
  File "/root/pycontrl/ctrlvenv/lib/python3.10/site-packages/starlette/routing.py", line 716, in __call__
    await self.middleware_stack(scope, receive, send)
  File "/root/pycontrl/ctrlvenv/lib/python3.10/site-packages/starlette/routing.py", line 736, in app
    await route.handle(scope, receive, send)
  File "/root/pycontrl/ctrlvenv/lib/python3.10/site-packages/starlette/routing.py", line 290, in handle
    await self.app(scope, receive, send)
  File "/root/pycontrl/ctrlvenv/lib/python3.10/site-packages/starlette/routing.py", line 78, in app
    await wrap_app_handling_exceptions(app, request)(scope, receive, send)
  File "/root/pycontrl/ctrlvenv/lib/python3.10/site-packages/starlette/_exception_handler.py", line 53, in wrapped_app
    raise exc
  File "/root/pycontrl/ctrlvenv/lib/python3.10/site-packages/starlette/_exception_handler.py", line 42, in wrapped_app
    await app(scope, receive, sender)
  File "/root/pycontrl/ctrlvenv/lib/python3.10/site-packages/starlette/routing.py", line 75, in app
    response = await f(request)
  File "/root/pycontrl/ctrlvenv/lib/python3.10/site-packages/fastapi/routing.py", line 302, in app
    raw_response = await run_endpoint_function(
  File "/root/pycontrl/ctrlvenv/lib/python3.10/site-packages/fastapi/routing.py", line 215, in run_endpoint_function
    return await run_in_threadpool(dependant.call, **values)
  File "/root/pycontrl/ctrlvenv/lib/python3.10/site-packages/starlette/concurrency.py", line 38, in run_in_threadpool
    return await anyio.to_thread.run_sync(func)
  File "/root/pycontrl/ctrlvenv/lib/python3.10/site-packages/anyio/to_thread.py", line 56, in run_sync
    return await get_async_backend().run_sync_in_worker_thread(
  File "/root/pycontrl/ctrlvenv/lib/python3.10/site-packages/anyio/_backends/_asyncio.py", line 2470, in run_sync_in_worker_thread
    return await future
  File "/root/pycontrl/ctrlvenv/lib/python3.10/site-packages/anyio/_backends/_asyncio.py", line 967, in run
    result = context.run(func, *args)
  File "/root/pycontrl/v1.2/boost_api.py", line 34, in stop_boost
    send_udp_message_and_receive_response("curr 6000")  # reset to normal current
  File "/root/pycontrl/v1.2/utils.py", line 82, in send_udp_message_and_receive_response
    sock.bind(('', port))  # Bind to same port to receive response (optional)
OSError: [Errno 98] Address already in use
INFO:     2a00:fbc:f3b3:c4c::2:0 - "POST /stop-boost HTTP/1.0" 200 OK
INFO:     2003:f3:2f28:41fc:4f66:73dc:aeea:f150:0 - "POST /temporary-charge HTTP/1.0" 200 OK
INFO:     2003:f3:2f28:41fc:4f66:73dc:aeea:f150:0 - "POST /stop-temporary-charge HTTP/1.0" 200 OK
INFO:     2003:f3:2f28:41fc:4f66:73dc:aeea:f150:0 - "POST /stop-temporary-charge HTTP/1.0" 200 OK
INFO:     2003:f3:2f28:41fc:4f66:73dc:aeea:f150:0 - "POST /temporary-charge HTTP/1.0" 500 Internal Server Error
ERROR:    Exception in ASGI application
Traceback (most recent call last):
  File "/root/pycontrl/ctrlvenv/lib/python3.10/site-packages/uvicorn/protocols/http/h11_impl.py", line 403, in run_asgi
    result = await app(  # type: ignore[func-returns-value]
  File "/root/pycontrl/ctrlvenv/lib/python3.10/site-packages/uvicorn/middleware/proxy_headers.py", line 60, in __call__
    return await self.app(scope, receive, send)
  File "/root/pycontrl/ctrlvenv/lib/python3.10/site-packages/fastapi/applications.py", line 1054, in __call__
    await super().__call__(scope, receive, send)
  File "/root/pycontrl/ctrlvenv/lib/python3.10/site-packages/starlette/applications.py", line 113, in __call__
    await self.middleware_stack(scope, receive, send)
  File "/root/pycontrl/ctrlvenv/lib/python3.10/site-packages/starlette/middleware/errors.py", line 186, in __call__
    raise exc
  File "/root/pycontrl/ctrlvenv/lib/python3.10/site-packages/starlette/middleware/errors.py", line 164, in __call__
    await self.app(scope, receive, _send)
  File "/root/pycontrl/ctrlvenv/lib/python3.10/site-packages/starlette/middleware/cors.py", line 93, in __call__
    await self.simple_response(scope, receive, send, request_headers=headers)
  File "/root/pycontrl/ctrlvenv/lib/python3.10/site-packages/starlette/middleware/cors.py", line 144, in simple_response
    await self.app(scope, receive, send)
  File "/root/pycontrl/ctrlvenv/lib/python3.10/site-packages/starlette/middleware/exceptions.py", line 63, in __call__
    await wrap_app_handling_exceptions(self.app, conn)(scope, receive, send)
  File "/root/pycontrl/ctrlvenv/lib/python3.10/site-packages/starlette/_exception_handler.py", line 53, in wrapped_app
    raise exc
  File "/root/pycontrl/ctrlvenv/lib/python3.10/site-packages/starlette/_exception_handler.py", line 42, in wrapped_app
    await app(scope, receive, sender)
  File "/root/pycontrl/ctrlvenv/lib/python3.10/site-packages/starlette/routing.py", line 716, in __call__
    await self.middleware_stack(scope, receive, send)
  File "/root/pycontrl/ctrlvenv/lib/python3.10/site-packages/starlette/routing.py", line 736, in app
    await route.handle(scope, receive, send)
  File "/root/pycontrl/ctrlvenv/lib/python3.10/site-packages/starlette/routing.py", line 290, in handle
    await self.app(scope, receive, send)
  File "/root/pycontrl/ctrlvenv/lib/python3.10/site-packages/starlette/routing.py", line 78, in app
    await wrap_app_handling_exceptions(app, request)(scope, receive, send)
  File "/root/pycontrl/ctrlvenv/lib/python3.10/site-packages/starlette/_exception_handler.py", line 53, in wrapped_app
    raise exc
  File "/root/pycontrl/ctrlvenv/lib/python3.10/site-packages/starlette/_exception_handler.py", line 42, in wrapped_app
    await app(scope, receive, sender)
  File "/root/pycontrl/ctrlvenv/lib/python3.10/site-packages/starlette/routing.py", line 75, in app
    response = await f(request)
  File "/root/pycontrl/ctrlvenv/lib/python3.10/site-packages/fastapi/routing.py", line 302, in app
    raw_response = await run_endpoint_function(
  File "/root/pycontrl/ctrlvenv/lib/python3.10/site-packages/fastapi/routing.py", line 215, in run_endpoint_function
    return await run_in_threadpool(dependant.call, **values)
  File "/root/pycontrl/ctrlvenv/lib/python3.10/site-packages/starlette/concurrency.py", line 38, in run_in_threadpool
    return await anyio.to_thread.run_sync(func)
  File "/root/pycontrl/ctrlvenv/lib/python3.10/site-packages/anyio/to_thread.py", line 56, in run_sync
    return await get_async_backend().run_sync_in_worker_thread(
  File "/root/pycontrl/ctrlvenv/lib/python3.10/site-packages/anyio/_backends/_asyncio.py", line 2470, in run_sync_in_worker_thread
    return await future
  File "/root/pycontrl/ctrlvenv/lib/python3.10/site-packages/anyio/_backends/_asyncio.py", line 967, in run
    result = context.run(func, *args)
  File "/root/pycontrl/v1.2/boost_api.py", line 43, in temporary_charge
    send_udp_message_and_receive_response("curr 6000")
  File "/root/pycontrl/v1.2/utils.py", line 82, in send_udp_message_and_receive_response
    sock.bind(('', port))  # Bind to same port to receive response (optional)
OSError: [Errno 98] Address already in use
INFO:     2003:f3:2f28:41fc:4f66:73dc:aeea:f150:0 - "POST /temporary-charge HTTP/1.0" 500 Internal Server Error
ERROR:    Exception in ASGI application
Traceback (most recent call last):
  File "/root/pycontrl/ctrlvenv/lib/python3.10/site-packages/uvicorn/protocols/http/h11_impl.py", line 403, in run_asgi
    result = await app(  # type: ignore[func-returns-value]
  File "/root/pycontrl/ctrlvenv/lib/python3.10/site-packages/uvicorn/middleware/proxy_headers.py", line 60, in __call__
    return await self.app(scope, receive, send)
  File "/root/pycontrl/ctrlvenv/lib/python3.10/site-packages/fastapi/applications.py", line 1054, in __call__
    await super().__call__(scope, receive, send)
  File "/root/pycontrl/ctrlvenv/lib/python3.10/site-packages/starlette/applications.py", line 113, in __call__
    await self.middleware_stack(scope, receive, send)
  File "/root/pycontrl/ctrlvenv/lib/python3.10/site-packages/starlette/middleware/errors.py", line 186, in __call__
    raise exc
  File "/root/pycontrl/ctrlvenv/lib/python3.10/site-packages/starlette/middleware/errors.py", line 164, in __call__
    await self.app(scope, receive, _send)
  File "/root/pycontrl/ctrlvenv/lib/python3.10/site-packages/starlette/middleware/cors.py", line 93, in __call__
    await self.simple_response(scope, receive, send, request_headers=headers)
  File "/root/pycontrl/ctrlvenv/lib/python3.10/site-packages/starlette/middleware/cors.py", line 144, in simple_response
    await self.app(scope, receive, send)
  File "/root/pycontrl/ctrlvenv/lib/python3.10/site-packages/starlette/middleware/exceptions.py", line 63, in __call__
    await wrap_app_handling_exceptions(self.app, conn)(scope, receive, send)
  File "/root/pycontrl/ctrlvenv/lib/python3.10/site-packages/starlette/_exception_handler.py", line 53, in wrapped_app
    raise exc
  File "/root/pycontrl/ctrlvenv/lib/python3.10/site-packages/starlette/_exception_handler.py", line 42, in wrapped_app
    await app(scope, receive, sender)
  File "/root/pycontrl/ctrlvenv/lib/python3.10/site-packages/starlette/routing.py", line 716, in __call__
    await self.middleware_stack(scope, receive, send)
  File "/root/pycontrl/ctrlvenv/lib/python3.10/site-packages/starlette/routing.py", line 736, in app
    await route.handle(scope, receive, send)
  File "/root/pycontrl/ctrlvenv/lib/python3.10/site-packages/starlette/routing.py", line 290, in handle
    await self.app(scope, receive, send)
  File "/root/pycontrl/ctrlvenv/lib/python3.10/site-packages/starlette/routing.py", line 78, in app
    await wrap_app_handling_exceptions(app, request)(scope, receive, send)
  File "/root/pycontrl/ctrlvenv/lib/python3.10/site-packages/starlette/_exception_handler.py", line 53, in wrapped_app
    raise exc
  File "/root/pycontrl/ctrlvenv/lib/python3.10/site-packages/starlette/_exception_handler.py", line 42, in wrapped_app
    await app(scope, receive, sender)
  File "/root/pycontrl/ctrlvenv/lib/python3.10/site-packages/starlette/routing.py", line 75, in app
    response = await f(request)
  File "/root/pycontrl/ctrlvenv/lib/python3.10/site-packages/fastapi/routing.py", line 302, in app
    raw_response = await run_endpoint_function(
  File "/root/pycontrl/ctrlvenv/lib/python3.10/site-packages/fastapi/routing.py", line 215, in run_endpoint_function
    return await run_in_threadpool(dependant.call, **values)
  File "/root/pycontrl/ctrlvenv/lib/python3.10/site-packages/starlette/concurrency.py", line 38, in run_in_threadpool
    return await anyio.to_thread.run_sync(func)
  File "/root/pycontrl/ctrlvenv/lib/python3.10/site-packages/anyio/to_thread.py", line 56, in run_sync
    return await get_async_backend().run_sync_in_worker_thread(
  File "/root/pycontrl/ctrlvenv/lib/python3.10/site-packages/anyio/_backends/_asyncio.py", line 2470, in run_sync_in_worker_thread
    return await future
  File "/root/pycontrl/ctrlvenv/lib/python3.10/site-packages/anyio/_backends/_asyncio.py", line 967, in run
    result = context.run(func, *args)
  File "/root/pycontrl/v1.2/boost_api.py", line 43, in temporary_charge
    send_udp_message_and_receive_response("curr 6000")
  File "/root/pycontrl/v1.2/utils.py", line 82, in send_udp_message_and_receive_response
    sock.bind(('', port))  # Bind to same port to receive response (optional)
OSError: [Errno 98] Address already in use
INFO:     2003:f3:2f28:41fc:4f66:73dc:aeea:f150:0 - "POST /temporary-charge HTTP/1.0" 500 Internal Server Error
ERROR:    Exception in ASGI application
Traceback (most recent call last):
  File "/root/pycontrl/ctrlvenv/lib/python3.10/site-packages/uvicorn/protocols/http/h11_impl.py", line 403, in run_asgi
    result = await app(  # type: ignore[func-returns-value]
  File "/root/pycontrl/ctrlvenv/lib/python3.10/site-packages/uvicorn/middleware/proxy_headers.py", line 60, in __call__
    return await self.app(scope, receive, send)
  File "/root/pycontrl/ctrlvenv/lib/python3.10/site-packages/fastapi/applications.py", line 1054, in __call__
    await super().__call__(scope, receive, send)
  File "/root/pycontrl/ctrlvenv/lib/python3.10/site-packages/starlette/applications.py", line 113, in __call__
    await self.middleware_stack(scope, receive, send)
  File "/root/pycontrl/ctrlvenv/lib/python3.10/site-packages/starlette/middleware/errors.py", line 186, in __call__
    raise exc
  File "/root/pycontrl/ctrlvenv/lib/python3.10/site-packages/starlette/middleware/errors.py", line 164, in __call__
    await self.app(scope, receive, _send)
  File "/root/pycontrl/ctrlvenv/lib/python3.10/site-packages/starlette/middleware/cors.py", line 93, in __call__
    await self.simple_response(scope, receive, send, request_headers=headers)
  File "/root/pycontrl/ctrlvenv/lib/python3.10/site-packages/starlette/middleware/cors.py", line 144, in simple_response
    await self.app(scope, receive, send)
  File "/root/pycontrl/ctrlvenv/lib/python3.10/site-packages/starlette/middleware/exceptions.py", line 63, in __call__
    await wrap_app_handling_exceptions(self.app, conn)(scope, receive, send)
  File "/root/pycontrl/ctrlvenv/lib/python3.10/site-packages/starlette/_exception_handler.py", line 53, in wrapped_app
    raise exc
  File "/root/pycontrl/ctrlvenv/lib/python3.10/site-packages/starlette/_exception_handler.py", line 42, in wrapped_app
    await app(scope, receive, sender)
  File "/root/pycontrl/ctrlvenv/lib/python3.10/site-packages/starlette/routing.py", line 716, in __call__
    await self.middleware_stack(scope, receive, send)
  File "/root/pycontrl/ctrlvenv/lib/python3.10/site-packages/starlette/routing.py", line 736, in app
    await route.handle(scope, receive, send)
  File "/root/pycontrl/ctrlvenv/lib/python3.10/site-packages/starlette/routing.py", line 290, in handle
    await self.app(scope, receive, send)
  File "/root/pycontrl/ctrlvenv/lib/python3.10/site-packages/starlette/routing.py", line 78, in app
    await wrap_app_handling_exceptions(app, request)(scope, receive, send)
  File "/root/pycontrl/ctrlvenv/lib/python3.10/site-packages/starlette/_exception_handler.py", line 53, in wrapped_app
    raise exc
  File "/root/pycontrl/ctrlvenv/lib/python3.10/site-packages/starlette/_exception_handler.py", line 42, in wrapped_app
    await app(scope, receive, sender)
  File "/root/pycontrl/ctrlvenv/lib/python3.10/site-packages/starlette/routing.py", line 75, in app
    response = await f(request)
  File "/root/pycontrl/ctrlvenv/lib/python3.10/site-packages/fastapi/routing.py", line 302, in app
    raw_response = await run_endpoint_function(
  File "/root/pycontrl/ctrlvenv/lib/python3.10/site-packages/fastapi/routing.py", line 215, in run_endpoint_function
    return await run_in_threadpool(dependant.call, **values)
  File "/root/pycontrl/ctrlvenv/lib/python3.10/site-packages/starlette/concurrency.py", line 38, in run_in_threadpool
    return await anyio.to_thread.run_sync(func)
  File "/root/pycontrl/ctrlvenv/lib/python3.10/site-packages/anyio/to_thread.py", line 56, in run_sync
    return await get_async_backend().run_sync_in_worker_thread(
  File "/root/pycontrl/ctrlvenv/lib/python3.10/site-packages/anyio/_backends/_asyncio.py", line 2470, in run_sync_in_worker_thread
    return await future
  File "/root/pycontrl/ctrlvenv/lib/python3.10/site-packages/anyio/_backends/_asyncio.py", line 967, in run
    result = context.run(func, *args)
  File "/root/pycontrl/v1.2/boost_api.py", line 43, in temporary_charge
    send_udp_message_and_receive_response("curr 6000")
  File "/root/pycontrl/v1.2/utils.py", line 82, in send_udp_message_and_receive_response
    sock.bind(('', port))  # Bind to same port to receive response (optional)
OSError: [Errno 98] Address already in use
INFO:     2003:f3:2f28:41fc:4f66:73dc:aeea:f150:0 - "POST /temporary-charge HTTP/1.0" 200 OK
INFO:     2003:f3:2f28:41fc:4f66:73dc:aeea:f150:0 - "POST /stop-temporary-charge HTTP/1.0" 200 OK
INFO:     88.217.234.182:0 - "POST /temporary-charge HTTP/1.0" 200 OK
INFO:     88.217.234.182:0 - "POST /stop-temporary-charge HTTP/1.0" 200 OK
✅ PSA response: 200 - {"_next_stop_hour":null,"_stop_hour":null,"percentage_threshold":80,"retry_count":0,"vin":"VR7EZZKXZPJ655855","wakeup_timeout":10}

INFO:     127.0.0.1:41390 - "POST /charge_limit_80 HTTP/1.1" 200 OK
✅ PSA response: 200 - {"_next_stop_hour":null,"_stop_hour":null,"percentage_threshold":80,"retry_count":0,"vin":"VR7EZZKXZPJ655855","wakeup_timeout":10}

INFO:     127.0.0.1:0 - "POST /charge_limit_80 HTTP/1.0" 200 OK
INFO:     127.0.0.1:42570 - "POST /charge_limit_100 HTTP/1.0" 200 OK
